Workbook

Sheet README
A1: REFERENTIEL_GRILLES_MATURITE_DIGITALE_JESA — Guide d'utilisation
A3: FINALITÉ DU CLASSEUR
A4: Ce classeur constitue la source officielle de configuration d'entrée inserer par l'utilisateur d'outil d'évaluation de la maturité digitale industrielle JESA. Il couvre 5 piliers, 10 dimensions, 20 sous-dimensions et 60 indicateurs, conformément à l'architecture définie au Chapitre 4 du rapport de PFA.
A6: STRUCTURE DU RÉFÉRENTIEL
A7: Le référentiel est organisé selon une hiérarchie à 4 niveaux : • Piliers (5) → Dimensions (10) → Sous-dimensions (20) → Indicateurs (60) L'agrégation des scores est ascendante : des indicateurs vers le DMI (Digital Maturity Index).
A9: RÔLE DE CHAQUE FEUILLE
A10: README : Ce guide d'utilisation.
A11: ASSESSMENT_METADATA: Saisie des informations de campagne d'évaluation.
A12: HIERARCHY : Référence complète des 20 sous-dimensions avec objectifs et risques.
A13: GENERIC_MATURITY_SCALE: Définition des 6 niveaux (0-5) applicables à l'ensemble du référentiel.
A14: DIMENSION_MATURITY_MATRICES: Description de ce que signifie chaque niveau (0-5) pour chacune des 10 dimensions.
A15: TARGET_LEVELS : Saisie des niveaux cibles par dimension (par l'évaluateur).
... A38: Par défaut, toutes les pondérations sont égales : • 2 sous-dimensions par dimension : 0,5 chacune • 2 dimensions par pilier : 0,5 chacune • 5 piliers : 0,2 chacun Toute personnalisation doit être documentée et justifiée dans WEIGHTS_CONFIGURATION.

Sheet ASSESSMENT_METADATA
A1: ASSESSMENT_METADATA — Informations de campagne d'évaluation
A2: Field_Name | B2: Field_Value | C2: Notes
A3: Assessment_ID | B3: JESA-ASSESS-001 | C3: Identifiant unique de la campagne. Format : JESA-ASSESS-NNN
A4: Site_ID | C4: Identifiant unique du site industriel évalué
A5: Site_Name | C5: Nom complet du site (ex : Laverie de phosphate Beni Amir)
A6: Industrial_Sector | C6: Secteur industriel (ex : Minier, Chimie, Agroalimentaire, Énergie)
A7: Plant_Unit | C7: Unité ou atelier évalué (ex : Unité de lavage, Section broyage)
A8: Location | C8: Localisation géographique du site
A9: Assessment_Date | C9: Date de début de l'évaluation (YYYY-MM-DD)
A10: Evaluator_Name | C10: Nom complet de l'évaluateur principal
A11: Evaluator_Function | C11: Fonction et organisation de l'évaluateur
A12: Assessment_Version | B12: 1.0.0 | C12: Version de cette campagne d'évaluation
A13: Reference_Framework_Version | B13: 1.0.0 | C13: Version du référentiel JESA utilisé
A14: General_Comments | C14: Observations générales sur le contexte de l'évaluation

Sheet HIERARCHY
A1: HIERARCHY — Architecture du référentiel (20 sous-dimensions)
A2: Pillar_ID | B2: Pillar_Name | C2: Dimension_ID | D2: Dimension_Name | E2: Subdimension_ID | F2: Subdimension_Name | G2: Dimension_Objective | H2: Subdimension_Objective | I2: Industrial_Capability | J2: Main_Risks_If_Weak
A3: P1 | B3: Infrastructure numérique | C3: D1 | D3: Infrastructure OT/IT | E3: SD1.1 | F3: Réseau OT & Disponibilité | G3: Garantir la robustesse, la disponibilité et la résilience de l'infrastructure numérique OT/IT du site | H3: Évaluer la couverture réseau, la redondance et la disponibilité des infrastructures OT sur le site | I3: Réseau industriel redondant, disponibilité ≥ 99,5 %, segmentation L0-L2 | J3: Défaillance réseau non détectée, perte de production non maîtrisée, absence de redondance
A4: P1 | B4: Infrastructure numérique | C4: D1 | D4: Infrastructure OT/IT | E4: SD1.2 | F4: Serveurs & Virtualisation | G4: Garantir la robustesse, la disponibilité et la résilience de l'infrastructure numérique OT/IT du site | H4: Évaluer le niveau de virtualisation, la capacité de réserve et la résilience des serveurs OT/IT | I4: Virtualisation déployée, capacité de réserve ≥ 30 %, restauration documentée | J4: Perte de données opérationnelles, temps de reprise inconnu, serveurs physiques obsolètes
A5: P1 | B5: Infrastructure numérique | C5: D2 | D5: Connectivité & Réseaux | E5: SD2.1 | F5: Protocoles & Interopérabilité | G5: Assurer la connectivité standardisée et l'intégration des systèmes OT et IT du site | H5: Évaluer l'utilisation de protocoles normalisés (OPC UA, Modbus TCP, PROFINET) pour les échanges OT | I5: Protocoles normalisés déployés, OPC UA opérationnel, interfaces documentées | J5: Données bloquées en silo, intégration systèmes impossible, protocoles propriétaires non évolutifs
A6: P1 | B6: Infrastructure numérique | C6: D2 | D6: Connectivité & Réseaux | E6: SD2.2 | F6: Intégration OT/IT | G6: Assurer la connectivité standardisée et l'intégration des systèmes OT et IT du site | H6: Évaluer la capacité des systèmes OT et IT à échanger des données de manière structurée et automatisée | I6: Intégration OT/IT bidirectionnelle, data node opérationnel, flux de données automatisés | J6: Silos OT/IT, décisions opérationnelles fondées sur des données manuelles, latence élevée
A7: P2 | B7: Opérations digitales | C7: D3 | D7: Automatisation & Contrôle | E7: SD3.1 | F7: Automates & Contrôle (DCS/PLC) | G7: Évaluer le niveau d'automatisation et de contrôle numérique des procédés de production | H7: Évaluer la couverture et la sophistication des systèmes de contrôle distribué (DCS) et automates (PLC) | I7: DCS/PLC couvrant ≥ 80 % des boucles critiques, paramétrage documenté, alarmes gérées | J7: Contrôle manuel des procédés, variabilité produit élevée, incidents non anticipés
A8: P2 | B8: Opérations digitales | C8: D3 | D8: Automatisation & Contrôle | E8: SD3.2 | F8: Système d'Exécution de la Fabrication (MES) & Ordonnancement | G8: Évaluer le niveau d'automatisation et de contrôle numérique des procédés de production | H8: Évaluer la capacité à planifier, suivre et optimiser l'exécution de la production via un MES | I8: MES déployé et interfacé au DCS, ordonnancement automatisé, traçabilité lots opérationnelle | J8: Absence de traçabilité production, ordonnancement manuel, écarts planifié/réel non analysés
A9: P2 | B9: Opérations digitales | C9: D4 | D9: Supervision & Monitoring | E9: SD4.1 | F9: Acquisition & Contrôle (SCADA) & Interface Opérateur (HMI) | G9: Évaluer la qualité de la supervision temps réel et la capacité de maintenance prédictive | H9: Évaluer la couverture SCADA, la qualité des IHM et la disponibilité des données temps réel pour les opérateurs | I9: SCADA couvrant l'ensemble du procédé, HMI standardisées, données temps réel accessibles salle de contrôle | J9: Supervision partielle, décisions opérateur sans données fiables, incidents détectés tardivement
A10: P2 | B10: Opérations digitales | C10: D4 | D10: Supervision & Monitoring | E10: SD4.2 | F10: Maintenance prédictive | G10: Évaluer la qualité de la supervision temps réel et la capacité de maintenance prédictive | H10: Évaluer la capacité à anticiper les défaillances d'équipements grâce à l'analyse de données capteurs | I10: Capteurs de surveillance déployés, algorithmes prédictifs actifs, alertes maintenance automatisées | J10: Maintenance uniquement curative, arrêts non planifiés fréquents, coûts maintenance élevés
A11: P3 | B11: Données & Intelligence | C11: D5 | D11: Gestion des données | E11: SD5.1 | F11: Historian & Traçabilité | G11: Évaluer la capacité à collecter, historiser et gouverner les données industrielles | H11: Évaluer l'existence, la couverture et la fiabilité du système d'historisation des données industrielles | I11: Historian opérationnel, rétention ≥ 12 mois, données horodatées et traçables jusqu'au capteur | J11: Perte de données historiques, impossibilité d'analyser les causes racines, non-conformité traçabilité
A12: P3 | B12: Données & Intelligence | C12: D5 | D12: Gestion des données | E12: SD5.2 | F12: Qualité & Gouvernance des données | G12: Évaluer la capacité à collecter, historiser et gouverner les données industrielles | H12: Évaluer l'existence de règles, rôles et processus garantissant la fiabilité et l'intégrité des données | I12: Politique qualité données formalisée, référentiel données défini, responsable données identifié | J12: Données non fiables pour la décision, doublons, erreurs non détectées, absence de référentiel
A13: P3 | B13: Données & Intelligence | C13: D6 | D13: Analyse & Intelligence Artificielle | E13: SD6.1 | F13: Analytique & Reporting | G13: Évaluer la capacité à valoriser les données par l'analytique et l'intelligence artificielle | H13: Évaluer la capacité à produire des analyses et tableaux de bord opérationnels à partir des données du site | I13: Tableaux de bord KPI temps réel, reporting automatisé, analyses causes racines documentées | J13: Pilotage par intuition, KPI calculés manuellement, rapports produits avec délai > 24h
... A22: P5 | B22: Capital humain & Compétences | C22: D10 | D22: Culture digitale & Organisation | E22: SD10.2 | F22: Innovation & Amélioration continue | G22: Évaluer la culture digitale et la capacité organisationnelle à innover | H22: Évaluer l'existence de processus structurés d'innovation digitale et d'amélioration continue des systèmes | I22: Démarche amélioration continue documentée, projets innovation digitale actifs, retours d'expérience intégrés | J22: Stagnation technologique, absence de veille, innovations non capitalisées

Sheet GENERIC_MATURITY_SCALE
A1: GENERIC_MATURITY_SCALE — Échelle de maturité générique (0-5)
A2: Level | B2: Level_Name | C2: Generic_Description | D2: Generic_Evaluation_Principle | E2: Minimum_Evidence_Principle
A3: 0 | B3: Absence | C3: Aucune initiative digitale identifiée. Les processus sont entièrement manuels ou analogiques. | D3: Constater l'absence totale d'outils numériques opérationnels dans le périmètre évalué. | E3: Aucun document, aucun outil, aucune mesure observable. Seule l'absence est constatable.
A4: 1 | B4: Informatisation | C4: Des outils numériques sont déployés ponctuellement pour remplacer certaines tâches manuelles. Les solutions restent locales, peu standardisées et fonctionnent indépendamment. | D4: Vérifier l'existence d'outils numériques déployés, même partiellement, sans intégration entre eux. | E4: Présence d'au moins un outil numérique opérationnel, même isolé. Documentation minimale existante.
A5: 2 | B5: Connectivité | C5: Les systèmes industriels et informatiques (OT/IT) sont interconnectés et échangent des données de manière fiable via des interfaces ou des protocoles normalisés. Les premières intégrations sont opérationnelles. | D5: Vérifier l'existence d'échanges de données structurés et fiables entre au moins deux systèmes distincts. | E5: Au moins une interface inter-systèmes documentée et opérationnelle. Protocole normalisé utilisé.
A6: 3 | B6: Visibilité | C6: Les données sont centralisées, historisées et accessibles en temps réel. Des tableaux de bord et des indicateurs de performance soutiennent le pilotage quotidien des opérations. | D6: Vérifier que les données sont accessibles en temps réel et utilisées pour le pilotage opérationnel. | E6: Tableau de bord opérationnel actif. Données historisées accessibles. KPI définis et affichés.
A7: 4 | B7: Maîtrise & Optimisation | C7: Les données sont exploitées pour analyser les performances, identifier les causes des écarts et mettre en œuvre des actions d'amélioration. Des fonctions d'analyse avancée et de maintenance prédictive sont en cours de déploiement. | D7: Vérifier que les analyses produisent des actions d'amélioration documentées et mesurables. | E7: Analyses causes racines documentées. Actions correctives tracées. Indicateurs de performance en amélioration.
A8: 5 | B8: Excellence digitale supervisée | C8: Les systèmes assistent ou automatisent la prise de décision grâce à des analyses avancées et à l'intelligence artificielle (IA). L'organisation est engagée dans une amélioration continue fondée sur les données, avec une gouvernance numérique pleinement maîtrisée. | D8: Vérifier que des systèmes d'aide à la décision automatisés sont opérationnels et produisent des résultats mesurables. | E8: Modèles prédictifs ou prescriptifs en production. Gouvernance numérique formalisée. Amélioration continue mesurée.

Sheet DIMENSION_MATURITY_MATRICES
A1: DIMENSION_MATURITY_MATRICES — Signification des niveaux 0-5 par dimension (60 lignes)
A2: Dimension_ID | B2: Dimension_Name | C2: Pillar_ID | D2: Level | E2: Level_Name | F2: Dimension_Level_Description | G2: Key_Capabilities_Expected | H2: Typical_Observed_State | I2: Minimum_Conditions | J2: Possible_Evidence | K2: Main_Limit_Preventing_Next_Level | L2: Recommended_Target_Use
A3: D1 | B3: Infrastructure OT/IT | C3: P1 | D3: 0 | E3: Absence | F3: Aucune infrastructure numérique OT spécifique. Les équipements de terrain fonctionnent sans réseau industriel dédié ni serveurs OT. | G3: Aucun | H3: Équipements autonomes, commande locale uniquement, aucun réseau industriel identifié | I3: Pas d'équipements réseau OT, pas de serveurs industriels, aucune documentation d'infrastructure | J3: Inventaire des équipements terrain, relevé terrain | K3: Absence de tout réseau OT structuré | L3: Valeur de référence. Non recommandé comme cible.
A4: D1 | B4: Infrastructure OT/IT | C4: P1 | D4: 1 | E4: Informatisation | F4: Des équipements OT individuels (automates, capteurs) sont en place mais non interconnectés. Des serveurs isolés peuvent exister pour des usages locaux spécifiques. | G4: Présence d'automates ou capteurs numériques isolés | H4: Automates indépendants, serveurs locaux dédiés à une fonction, absence de réseau unificateur | I4: Au moins un automate numérique opérationnel, au moins un serveur local en service | J4: Liste des équipements OT, fiches techniques automates | K4: Absence de réseau OT fédérateur reliant les équipements | L4: Applicable uniquement aux sites en phase initiale de numérisation.
A5: D1 | B5: Infrastructure OT/IT | C5: P1 | D5: 2 | E5: Connectivité | F5: Un réseau OT est déployé sur une partie significative du site. Les équipements de terrain sont connectés via un réseau industriel structuré. Des serveurs partagés sont opérationnels. | G5: Réseau OT déployé sur ≥ 50 % des équipements critiques, serveurs partagés en service | H5: Réseau Ethernet industriel opérationnel, serveurs OT accessibles depuis la salle de contrôle | I5: Architecture réseau OT documentée, au moins 50 % des équipements critiques connectés | J5: Schéma réseau OT, liste des équipements connectés, journal des incidents réseau | K5: Absence de redondance réseau, couverture partielle, virtualisation non déployée | L5: Cible minimale pour un site en cours de modernisation.
A6: D1 | B6: Infrastructure OT/IT | C6: P1 | D6: 3 | E6: Visibilité | F6: L'infrastructure OT est complète et documentée. La topologie réseau est connue et maintenue. La virtualisation est déployée pour les fonctions critiques. La disponibilité est mesurée. | G6: Réseau OT couvrant ≥ 90 % du site, virtualisation déployée sur serveurs critiques, disponibilité mesurée | H6: Infrastructure documentée, supervision réseau active (NMS), indicateurs de disponibilité affichés | I6: Architecture réseau complète documentée, NMS opérationnel, virtualisation active, disponibilité ≥ 99 % | J6: Schéma réseau à jour, tableaux de bord NMS, rapports de disponibilité mensuels | K6: Absence de redondance N+1 sur chemins critiques, plan de reprise non formalisé | L6: Cible recommandée pour la majorité des sites industriels.
A7: D1 | B7: Infrastructure OT/IT | C7: P1 | D7: 4 | E7: Maîtrise & Optimisation | F7: L'infrastructure est redondante, résiliente et gérée de manière proactive. Les anomalies sont détectées automatiquement. La capacité de réserve est planifiée et documentée. | G7: Redondance N+1 sur chemins critiques, détection automatique des anomalies, capacité de réserve ≥ 30 % | H7: Infrastructure supervisée en temps réel, alertes automatiques sur incidents, plan de capacité actif | I7: Redondance documentée et testée, capacité de réserve ≥ 30 % sur serveurs et réseau, procédures de bascule | J7: Tests de bascule documentés, rapports de capacité, historique d'incidents résolus | K7: Absence de mécanismes d'auto-guérison ou d'optimisation dynamique du réseau | L7: Cible pour les sites à enjeux de continuité de production élevés.
A8: D1 | B8: Infrastructure OT/IT | C8: P1 | D8: 5 | E8: Excellence digitale supervisée | F8: Infrastructure entièrement résiliente et auto-adaptative. Gestion prédictive de la capacité. Virtualisation complète avec orchestration. Métriques d'infrastructure alimentent les décisions opérationnelles. | G8: Infrastructure définie par logiciel (SDN/virtualisation complète), gestion prédictive de capacité, zéro interruption non planifiée | H8: Auto-guérison du réseau, provisionnement dynamique, SLA d'infrastructure mesurés et tenus | I8: Plan de capacité prédictif actif, SLA infrastructure ≥ 99,9 %, aucune interruption non planifiée sur 12 mois | J8: Rapports SLA, modèles de prédiction de capacité, historique zéro incident non planifié | K8: Aucun — niveau d'excellence | L8: Cible pour les sites à haute criticité ou programmes d'excellence opérationnelle.
A9: D2 | B9: Connectivité & Réseaux | C9: P1 | D9: 0 | E9: Absence | F9: Aucun protocole industriel normalisé. Les échanges entre systèmes sont inexistants ou entièrement manuels (fichiers CSV, saisie manuelle). | G9: Aucun | H9: Systèmes totalement cloisonnés, aucun échange automatisé de données | I9: Aucune interface inter-systèmes, aucun protocole industriel documenté | J9: Relevé terrain, entretiens opérateurs | K9: Absence de tout protocole normalisé | L9: Non recommandé comme cible.
A10: D2 | B10: Connectivité & Réseaux | C10: P1 | D10: 1 | E10: Informatisation | F10: Des protocoles propriétaires ou des échanges manuels de fichiers existent entre certains systèmes. Les premières tentatives d'intégration sont en place mais non standardisées. | G10: Au moins un protocole de communication actif (même propriétaire) | H10: Échanges de fichiers CSV/Excel entre systèmes, protocoles propriétaires par équipement | I10: Au moins un mécanisme d'échange de données entre systèmes, même manuel | J10: Fichiers d'échange, documentation des interfaces existantes | K10: Absence de protocoles normalisés, intégrations non documentées | L10: Applicable en phase initiale uniquement.
A11: D2 | B11: Connectivité & Réseaux | C11: P1 | D11: 2 | E11: Connectivité | F11: Des protocoles industriels normalisés (Modbus TCP, OPC DA, PROFINET) sont déployés sur au moins 50 % des interfaces critiques. Les premières intégrations OT/IT sont opérationnelles. | G11: Protocoles normalisés sur ≥ 50 % des interfaces, au moins une intégration OT/IT fonctionnelle | H11: Modbus TCP ou équivalent déployé, OPC DA ou similaire actif sur certains systèmes | I11: Au moins 50 % des interfaces critiques documentées avec protocole normalisé | J11: Liste des interfaces, documentation protocoles, tests de communication | K11: OPC DA déprécié, migration OPC UA non initiée, absence de serveur d'interopérabilité centralisé | L11: Cible minimale pour débuter l'intégration OT/IT.
A12: D2 | B12: Connectivité & Réseaux | C12: P1 | D12: 3 | E12: Visibilité | F12: OPC UA ou équivalent déployé sur les interfaces principales. Un serveur d'interopérabilité centralisé est opérationnel. L'intégration L2-L3 est réalisée pour les données critiques. | G12: OPC UA déployé, serveur d'interopérabilité opérationnel, intégration L2-L3 active | H12: OPC UA Server VM opérationnel, données process accessibles au niveau L3 | I12: OPC UA Server déployé et documenté, intégration L2-L3 pour ≥ 80 % des données critiques | J12: Documentation OPC UA, schéma d'intégration L2-L3, rapports de flux de données | K12: Intégration L3-L4 (vers ERP/IT) non encore réalisée | L12: Cible standard pour tout site industriel moderne.
A13: D2 | B13: Connectivité & Réseaux | C13: P1 | D13: 4 | E13: Maîtrise & Optimisation | F13: Intégration verticale complète L0-L4. Tous les systèmes clés communiquent via des protocoles normalisés. Les flux de données sont monitorés et documentés. Latence et fiabilité mesurées. | G13: Intégration L0-L4 complète, monitoring des flux, latence < seuils définis | H13: Data Node opérationnel, tous les systèmes intégrés, monitoring des échanges actif | I13: Intégration documentée L0-L4, monitoring des flux de données, SLA de latence définis et mesurés | J13: Schémas d'intégration complets, rapports de monitoring des flux, historique de latence | K13: Absence d'optimisation dynamique des flux, gestion manuelle des incidents d'intégration | L13: Cible pour sites à forte dépendance d'intégration systèmes.
A14: D2 | B14: Connectivité & Réseaux | C14: P1 | D14: 5 | E14: Excellence digitale supervisée | F14: Architecture d'intégration auto-adaptative. Gestion dynamique des protocoles. Intégration temps réel avec systèmes cloud et edge. Les données circulent sans latence perceptible pour l'opérateur. | G14: Architecture data fabric, intégration temps réel multisite, protocoles auto-adaptés | H14: Échanges temps réel multisite, intégration cloud/edge opérationnelle, zéro point de rupture de flux | I14: SLA d'intégration ≥ 99,9 %, latence < 100 ms sur échanges critiques, aucune perte de données | J14: Rapports SLA intégration, monitoring temps réel des flux, historique performances | K14: Aucun — niveau d'excellence | L14: Cible pour programmes d'intégration avancée multisite.
... A62: D10 | B62: Culture digitale & Organisation | C62: P5 | D62: 5 | E62: Excellence digitale supervisée | F62: Culture d'innovation digitale pleinement ancrée. Collaboration avec startups, universités ou écosystèmes digitaux externes. Le site est reconnu comme référence en transformation digitale. | G62: Innovation ouverte, collaborations externes, site référence digitale | H62: Partenariats actifs avec écosystème digital, visites de pairs, ≥ 1 prix ou reconnaissance | I62: ≥ 1 partenariat externe d'innovation actif, site visité par pairs | J62: Conventions de partenariat, compte-rendus visites pairs | K62: Aucun | L62: Cible pour sites leaders.

Sheet TARGET_LEVELS
A1: TARGET_LEVELS — Niveaux cibles par dimension (saisie évaluateur)
A2: Dimension_ID | B2: Dimension_Name | C2: Target_Level_Default | D2: Target_Level_User | E2: Effective_Target_Level | F2: Target_Level_Description
A3: D1 | B3: Infrastructure OT/IT | C3: 3 | E3: =IF(D3<>"",D3,C3) -> 3 | F3: Réseau OT complet documenté, virtualisation déployée, disponibilité mesurée.
A4: D2 | B4: Connectivité & Réseaux | C4: 3 | E4: =IF(D4<>"",D4,C4) -> 3 | F4: OPC UA déployé, intégration L2-L3 active, serveur interopérabilité opérationnel.
A5: D3 | B5: Automatisation & Contrôle | C5: 3 | E5: =IF(D5<>"",D5,C5) -> 3 | F5: DCS couvrant ≥ 90 % procédé, MES déployé, traçabilité production active.
A6: D4 | B6: Supervision & Monitoring | C6: 3 | E6: =IF(D6<>"",D6,C6) -> 3 | F6: SCADA global, HMI standardisées, gestion alarmes documentée.
A7: D5 | B7: Gestion des données | C7: 3 | E7: =IF(D7<>"",D7,C7) -> 3 | F7: Historian complet ≥ 12 mois, politique qualité données approuvée.
A8: D6 | B8: Analyse & Intelligence Artificielle | C8: 3 | E8: =IF(D8<>"",D8,C8) -> 3 | F8: Plateforme BI active, ≥ 20 KPI automatisés, analyses causes racines.
A9: D7 | B9: Cybersécurité OT/IT | C9: 3 | E9: =IF(D9<>"",D9,C9) -> 3 | F9: DMZ L3.5, AD OT, monitoring sécurité, patch management.
A10: D8 | B10: Gouvernance numérique | C10: 3 | E10: =IF(D10<>"",D10,C10) -> 3 | F10: Comité digital actif, KPI gouvernance, gestion du changement appliquée.
A11: D9 | B11: Compétences & Formation | C11: 3 | E11: =IF(D11<>"",D11,C11) -> 3 | F11: Plan formation exécuté, budget dédié, évaluations post-formation.
A12: D10 | B12: Culture digitale & Organisation | C12: 3 | E12: =IF(D12<>"",D12,C12) -> 3 | F12: Adoption ≥ 80 %, REX actif, idées d'amélioration traitées.
A14: ⚠ RÈGLE : Le niveau cible (colonne D) doit être saisi par l'évaluateur. Si omis, la valeur par défaut (colonne C) s'applique.

Sheet WEIGHTS_CONFIGURATION
A1: WEIGHTS_CONFIGURATION — Configuration des pondérations
A2: Hierarchy_Level | B2: Parent_ID | C2: Component_ID | D2: Component_Name | E2: Default_Weight | F2: User_Defined_Weight | G2: Effective_Weight | H2: Weight_Source | I2: Justification | J2: Validation_Status
A3: Pilier | B3: DMI | C3: P1 | D3: Infrastructure numérique | E3: 0.2 | G3: =IF(F3<>"",F3,E3) -> 0.2 | H3: Défaut | I3: Pondération égale entre les 5 piliers. Configurable si contexte justifié. | J3: À valider
A4: Pilier | B4: DMI | C4: P2 | D4: Opérations digitales | E4: 0.2 | G4: =IF(F4<>"",F4,E4) -> 0.2 | H4: Défaut | I4: Pondération égale entre les 5 piliers. Configurable si contexte justifié. | J4: À valider
A5: Pilier | B5: DMI | C5: P3 | D5: Données & Intelligence | E5: 0.2 | G5: =IF(F5<>"",F5,E5) -> 0.2 | H5: Défaut | I5: Pondération égale entre les 5 piliers. Configurable si contexte justifié. | J5: À valider
A6: Pilier | B6: DMI | C6: P4 | D6: Gouvernance & Cybersécurité | E6: 0.2 | G6: =IF(F6<>"",F6,E6) -> 0.2 | H6: Défaut | I6: Pondération égale entre les 5 piliers. Configurable si contexte justifié. | J6: À valider
A7: Pilier | B7: DMI | C7: P5 | D7: Capital humain & Compétences | E7: 0.2 | G7: =IF(F7<>"",F7,E7) -> 0.2 | H7: Défaut | I7: Pondération égale entre les 5 piliers. Configurable si contexte justifié. | J7: À valider
A8: Dimension | B8: P1 | C8: D1 | D8: Infrastructure OT/IT | E8: 0.5 | G8: =IF(F8<>"",F8,E8) -> 0.5 | H8: Défaut | I8: Pondération égale entre les 2 dimensions du pilier. Configurable. | J8: À valider
A9: Dimension | B9: P1 | C9: D2 | D9: Connectivité & Réseaux | E9: 0.5 | G9: =IF(F9<>"",F9,E9) -> 0.5 | H9: Défaut | I9: Pondération égale entre les 2 dimensions du pilier. Configurable. | J9: À valider
A10: Dimension | B10: P2 | C10: D3 | D10: Automatisation & Contrôle | E10: 0.5 | G10: =IF(F10<>"",F10,E10) -> 0.5 | H10: Défaut | I10: Pondération égale entre les 2 dimensions du pilier. Configurable. | J10: À valider
A11: Dimension | B11: P2 | C11: D4 | D11: Supervision & Monitoring | E11: 0.5 | G11: =IF(F11<>"",F11,E11) -> 0.5 | H11: Défaut | I11: Pondération égale entre les 2 dimensions du pilier. Configurable. | J11: À valider
A12: Dimension | B12: P3 | C12: D5 | D12: Gestion des données | E12: 0.5 | G12: =IF(F12<>"",F12,E12) -> 0.5 | H12: Défaut | I12: Pondération égale entre les 2 dimensions du pilier. Configurable. | J12: À valider
A13: Dimension | B13: P3 | C13: D6 | D13: Analyse & Intelligence Artificielle | E13: 0.5 | G13: =IF(F13<>"",F13,E13) -> 0.5 | H13: Défaut | I13: Pondération égale entre les 2 dimensions du pilier. Configurable. | J13: À valider
A14: Dimension | B14: P4 | C14: D7 | D14: Cybersécurité OT/IT | E14: 0.5 | G14: =IF(F14<>"",F14,E14) -> 0.5 | H14: Défaut | I14: Pondération égale entre les 2 dimensions du pilier. Configurable. | J14: À valider
... A37: Sous-dimension | B37: D10 | C37: SD10.2 | D37: Innovation & Amélioration continue | E37: 0.5 | G37: =IF(F37<>"",F37,E37) -> 0.5 | H37: Défaut | I37: Pondération égale entre les 2 sous-dimensions de la dimension. Configurable. | J37: À valider
A39: ⚠ RÈGLE CRITIQUE : La somme des poids effectifs des enfants d'un même parent doit toujours être égale à 1. Vérifier dans QUALITY_CONTROL. Tout écart aux poids par défaut doit être justifié dans la colonne Justification.

Sheet INDICATORS
A1: INDICATORS — 60 indicateurs d'évaluation (3 par sous-dimension)
A2: Indicator_ID | B2: Pillar_ID | C2: Dimension_ID | D2: Subdimension_ID | E2: Indicator_Name | F2: Indicator_Objective | G2: Assessment_Question | H2: Indicator_Type | I2: Measurement_Mode | J2: Expected_Respondent | K2: Assessment_Perimeter | L2: Applicability_Condition | M2: Required_Evidence_Category | N2: Gap_Trigger_Code | O2: Source_Reference | P2: Assumptions | Q2: Expert_Validation_Status
A3: I-D1-01 | B3: P1 | C3: D1 | D3: SD1.1 | E3: Couverture réseau OT | F3: Évaluer le pourcentage des équipements de terrain connectés au réseau industriel OT | G3: Quel est le pourcentage des équipements de terrain (automates, capteurs, actionneurs) connectés à un réseau industriel OT structuré ? | H3: Quantitatif | I3: Mesure documentée | J3: Ingénieur instrumentation / Responsable OT | K3: Ensemble du site | L3: Aucune | M3: Architecture réseau, inventaire équipements | N3: GAP-SD1.1-COV | O3: Chapitre 4 JESA ; Mining 5.0 DAL | P3: Indicateur 100 % observable sur schémas réseau | Q3: À valider
A4: I-D1-02 | B4: P1 | C4: D1 | D4: SD1.1 | E4: Redondance réseau OT | F4: Évaluer l'existence et la couverture de la redondance sur les chemins réseau critiques OT | G4: Les chemins réseau critiques OT (liens entre contrôleurs et salle de contrôle) bénéficient-ils d'une redondance documentée et testée ? | H4: Qualitatif | I4: Observation + documentation | J4: Ingénieur réseau OT / Responsable infrastructure | K4: Réseau OT critique | L4: Aucune | M4: Architecture réseau, tests de bascule | N4: GAP-SD1.1-RED | O4: Chapitre 4 JESA | P4: Basé sur schémas réseau et tests documentés | Q4: À valider
A5: I-D1-03 | B5: P1 | C5: D1 | D5: SD1.1 | E5: Disponibilité réseau OT mesurée | F5: Évaluer si la disponibilité du réseau OT est mesurée, enregistrée et comparée à un objectif défini | G5: La disponibilité du réseau industriel OT est-elle mesurée automatiquement et comparée à un objectif de disponibilité documenté ? | H5: Qualitatif | I5: Documentation + outil NMS | J5: Administrateur réseau OT | K5: Infrastructure réseau | L5: Aucune | M5: Rapports NMS, paramètres de disponibilité cible | N5: GAP-SD1.1-AVL | O5: Chapitre 4 JESA ; Mining 5.0 NMS Server | P5: Requiert NMS opérationnel | Q5: À valider
A6: I-D1-04 | B6: P1 | C6: D1 | D6: SD1.2 | E6: Virtualisation serveurs OT | F6: Évaluer le niveau de déploiement de la virtualisation sur les serveurs industriels OT | G6: Les serveurs industriels OT (historian, SCADA, DCS serveur) sont-ils déployés sur une infrastructure virtualisée ? | H6: Quantitatif | I6: Inventaire + documentation | J6: Administrateur serveurs / Responsable IT-OT | K6: Serveurs OT | L6: Aucune | M6: Inventaire serveurs, configuration virtualisation | N6: GAP-SD1.2-VIRT | O6: Chapitre 4 JESA ; Mining 5.0 Plant Virtual Hosts | P6: Directement observable | Q6: À valider
A7: I-D1-05 | B7: P1 | C7: D1 | D7: SD1.2 | E7: Capacité de réserve serveurs | F7: Évaluer si les serveurs OT disposent d'une capacité de réserve (CPU, RAM, stockage) permettant l'extension | G7: Les serveurs OT disposent-ils d'une capacité de réserve documentée d'au moins 30 % sur les ressources critiques (CPU, RAM, stockage) ? | H7: Quantitatif | I7: Mesure système | J7: Administrateur serveurs | K7: Serveurs OT | L7: Aucune | M7: Rapports utilisation ressources, documenté dans spécifications | N7: GAP-SD1.2-CAP | O7: Réquisition Beni Amir item 2 (30 % spare) | P7: Chiffre 30 % tiré de la réquisition Beni Amir, à adapter au contexte | Q7: À valider
A8: I-D1-06 | B8: P1 | C8: D1 | D8: SD1.2 | E8: Plan de reprise d'activité OT | F8: Évaluer l'existence et la validité d'un plan de reprise d'activité documenté pour les serveurs OT | G8: Un plan de reprise d'activité (DRP) pour les serveurs OT est-il documenté, testé et à jour ? | H8: Qualitatif | I8: Revue documentaire | J8: Responsable infrastructure / Direction technique | K8: Serveurs OT critiques | L8: Aucune | M8: Plan DRP, compte-rendu test DRP | N8: GAP-SD1.2-DRP | O8: Chapitre 4 JESA | P8: Test DRP : simulacre documenté requis pour niveau 4 | Q8: À valider
A9: I-D2-01 | B9: P1 | C9: D2 | D9: SD2.1 | E9: Standardisation des protocoles industriels | F9: Évaluer si les échanges de données entre équipements industriels utilisent des protocoles normalisés | G9: Les échanges de données entre automates, capteurs et systèmes de supervision utilisent-ils des protocoles industriels normalisés (Modbus TCP, PROFINET, OPC UA ou équivalent) ? | H9: Qualitatif | I9: Revue documentation technique | J9: Ingénieur automatisme / Responsable OT | K9: Réseau industriel OT | L9: Aucune | M9: Documentation des interfaces, liste des protocoles utilisés | N9: GAP-SD2.1-PROTO | O9: Chapitre 4 JESA ; Réquisition Beni Amir item 5 | P9: Basé sur documentation technique disponible | Q9: À valider
A10: I-D2-02 | B10: P1 | C10: D2 | D10: SD2.1 | E10: Déploiement OPC UA | F10: Évaluer le niveau de déploiement du protocole OPC UA comme standard d'interopérabilité | G10: Un serveur OPC UA est-il déployé et opérationnel pour assurer les échanges de données entre les systèmes OT et les systèmes de niveau supérieur (MES, ERP, cloud) ? | H10: Qualitatif | I10: Observation + test | J10: Ingénieur automatisme / Administrateur OPC UA | K10: Interfaces OT-IT | L10: Aucune | M10: Configuration OPC UA Server, tests de communication | N10: GAP-SD2.1-OPCUA | O10: Réquisition Beni Amir item 5 & 15 ; DCS Spec Q12203-00-IC-SPC-00005 | P10: Directement testable | Q10: À valider
A11: I-D2-03 | B11: P1 | C11: D2 | D11: SD2.1 | E11: Documentation des interfaces inter-systèmes | F11: Évaluer l'existence et la qualité de la documentation des interfaces de communication entre systèmes | G11: Toutes les interfaces de communication entre les systèmes industriels (DCS, SCADA, MES, historian, ERP) sont-elles documentées avec les protocoles, formats et fréquences d'échange ? | H11: Qualitatif | I11: Revue documentaire | J11: Ingénieur systèmes / Responsable OT | K11: Interfaces inter-systèmes | L11: Aucune | M11: Matrices d'interfaces, documentation API, schémas de flux | N11: GAP-SD2.1-DOCIF | O11: Chapitre 4 JESA | P11: Revue documentaire directe | Q11: À valider
A12: I-D2-04 | B12: P1 | C12: D2 | D12: SD2.2 | E12: Intégration OT/IT bidirectionnelle | F12: Évaluer si les données OT remontent automatiquement vers les systèmes IT et vice-versa | G12: Les données de procédé (niveaux L0-L2) remontent-elles automatiquement vers les systèmes de gestion (niveaux L3-L4) sans intervention manuelle ? | H12: Qualitatif | I12: Test + documentation | J12: Ingénieur intégration / Responsable OT | K12: Flux OT vers IT | L12: Aucune | M12: Schéma d'intégration, logs de flux de données, Data Node configuration | N12: GAP-SD2.2-INTEG | O12: Chapitre 4 JESA ; Mining 5.0 Site Data Node | P12: Basé sur test de flux de données | Q12: À valider
A13: I-D2-05 | B13: P1 | C13: D2 | D13: SD2.2 | E13: Monitoring des flux de données OT/IT | F13: Évaluer si les flux de données entre OT et IT sont supervisés avec alertes en cas d'anomalie | G13: Les flux de données entre les systèmes OT et IT sont-ils supervisés automatiquement, avec des alertes configurées en cas d'interruption ou de dégradation ? | H13: Qualitatif | I13: Observation outil de monitoring | J13: Administrateur réseau / Responsable IT-OT | K13: Flux de données inter-systèmes | L13: Aucune | M13: Configuration monitoring, logs d'alertes, tableaux de bord NMS | N13: GAP-SD2.2-MON | O13: Chapitre 4 JESA ; Mining 5.0 Log Manager VM | P13: Requiert outil de monitoring actif | Q13: À valider
... A62: I-D10-06 | B62: P5 | C62: D10 | D62: SD10.2 | E62: Veille technologique et partenariats d'innovation actifs | F62: Évaluer si une veille technologique digitale et des partenariats d'innovation sont en place | G62: Une démarche de veille technologique digitale est-elle active et le site entretient-il des partenariats formalisés avec des acteurs de l'innovation (startups, universités, clusters) ? | H62: Qualitatif | I62: Entretien + revue documentaire | J62: Direction / Responsable digital | K62: Écosystème d'innovation | L62: Aucune | M62: Rapports de veille, conventions de partenariat, comptes-rendus d'événements | N62: GAP-SD10.2-VEIL | O62: Chapitre 4 JESA | P62: Partenariat formalisé requis pour niveau 5 | Q62: À valider

Sheet INDICATOR_SCORING_GRIDS
A1: INDICATOR_SCORING_GRIDS — 360 grilles de scoring (60 indicateurs × 6 niveaux)
A2: Indicator_ID | B2: Assessment_Question | C2: Score | D2: Score_Label | E2: Observable_Situation | F2: Mandatory_Criteria | G2: Possible_Evidence | H2: Disqualifying_Conditions | I2: Evaluator_Guidance | J2: Next_Score_Requirement | K2: Source_Reference | L2: Expert_Validation_Status
A3: I-D1-01 | B3: % équipements terrain connectés au réseau OT structuré ? | C3: 0 | D3: Absence | E3: Aucun équipement de terrain n'est connecté à un réseau industriel OT structuré. Toute communication est locale ou absente. | F3: Absence totale de réseau OT | G3: Relevé terrain confirmant l'absence | H3: Présence d'un seul câble réseau industriel | I3: Vérifier l'ensemble des zones du site | J3: Déployer un réseau OT industriel sur au moins 30 % des équipements | K3: Chapitre 4 JESA | L3: À valider
A4: I-D1-01 | B4: % équipements terrain connectés au réseau OT structuré ? | C4: 1 | D4: Informatisation | E4: Moins de 30 % des équipements de terrain sont connectés à un réseau industriel OT. Les connexions existantes sont isolées ou non standardisées. | F4: Au moins 1 équipement connecté, couverture < 30 % | G4: Schéma réseau partiel, liste des équipements | H4: Couverture ≥ 30 % des équipements | I4: Estimer la couverture depuis les schémas réseau disponibles | J4: Atteindre ≥ 50 % de couverture avec un réseau structuré | K4: Chapitre 4 JESA | L4: À valider
A5: I-D1-01 | B5: % équipements terrain connectés au réseau OT structuré ? | C5: 2 | D5: Connectivité | E5: Entre 30 % et 69 % des équipements critiques sont connectés à un réseau industriel OT structuré. L'architecture réseau est partiellement documentée. | F5: Couverture réseau OT entre 30 % et 69 % des équipements critiques | G5: Schéma réseau OT partiel, liste équipements connectés | H5: Couverture < 30 % ou réseau non documenté | I5: Exiger un schéma réseau actualisé | J5: Atteindre ≥ 70 % de couverture avec documentation complète | K5: Chapitre 4 JESA | L5: À valider
A6: I-D1-01 | B6: % équipements terrain connectés au réseau OT structuré ? | C6: 3 | D6: Visibilité | E6: Entre 70 % et 89 % des équipements critiques sont connectés. L'architecture réseau OT est documentée et maintenue à jour. Un outil NMS supervise le réseau. | F6: Couverture réseau OT 70 %-89 %, NMS actif, architecture documentée | G6: Architecture réseau à jour, NMS opérationnel, couverture ≥ 70 % | H6: Couverture < 70 % ou NMS absent | I6: Vérifier la date de mise à jour de l'architecture réseau | J6: Atteindre ≥ 90 % de couverture avec redondance sur chemins critiques | K6: Chapitre 4 JESA | L6: À valider
A7: I-D1-01 | B7: % équipements terrain connectés au réseau OT structuré ? | C7: 4 | D7: Maîtrise & Optimisation | E7: 90 % ou plus des équipements critiques sont connectés. La redondance est déployée sur les chemins critiques. Les incidents réseau sont détectés automatiquement. | F7: Couverture ≥ 90 %, redondance documentée et testée sur chemins critiques | G7: Architecture complète, tests de bascule documentés, alertes automatiques | H7: Couverture < 90 % ou redondance non testée | I7: Demander les comptes-rendus de tests de bascule | J7: Déployer une gestion prédictive de la capacité réseau | K7: Chapitre 4 JESA | L7: À valider
A8: I-D1-01 | B8: % équipements terrain connectés au réseau OT structuré ? | C8: 5 | D8: Excellence digitale supervisée | E8: 100 % des équipements critiques connectés. Architecture réseau définie logiciellement (SDN ou équivalent). Aucune interruption non planifiée sur 12 mois. Capacity planning prédictif actif. | F8: Couverture 100 %, zéro interruption non planifiée sur 12 mois, capacity planning | G8: Historique d'incidents réseau, rapport capacity planning, architecture SDN | H8: Toute interruption non planifiée dans l'année écoulée | I8: Examiner le journal des incidents réseau sur 12 mois | J8: Niveau d'excellence - maintenir et améliorer | K8: Chapitre 4 JESA | L8: À valider
A9: I-D1-02 | B9: Les chemins réseau critiques OT bénéficient-ils d'une redondance testée ? | C9: 0 | D9: Absence | E9: Aucun chemin réseau redondant. Un seul câble ou switch relie les contrôleurs à la salle de contrôle. Toute défaillance de liaison entraîne une perte totale de supervision. | F9: Absence de toute redondance | G9: Schéma réseau confirmant l'absence de redondance | H9: Présence d'un second chemin, même non documenté | I9: Vérifier les schémas synoptiques réseau | J9: Documenter les chemins critiques et planifier leur redondance | K9: Chapitre 4 JESA | L9: À valider
A10: I-D1-02 | B10: Les chemins réseau critiques OT bénéficient-ils d'une redondance testée ? | C10: 1 | D10: Informatisation | E10: Une redondance partielle existe sur certains tronçons, mais elle n'est pas documentée, testée ni gérée formellement. | F10: Redondance partielle non documentée | G10: Observation terrain, traces de câbles secondaires | H10: Redondance documentée ou testée | I10: Inspecter physiquement l'infrastructure réseau | J10: Documenter les chemins redondants existants | K10: Chapitre 4 JESA | L10: À valider
A11: I-D1-02 | B11: Les chemins réseau critiques OT bénéficient-ils d'une redondance testée ? | C11: 2 | D11: Connectivité | E11: La redondance est déployée sur au moins un chemin critique et est documentée dans l'architecture réseau. Non testée formellement. | F11: Redondance documentée sur ≥ 1 chemin critique | G11: Architecture réseau mentionnant la redondance | H11: Redondance non documentée ou non vérifiable | I11: Croiser schéma réseau et inspection terrain | J11: Tester la bascule et formaliser la procédure | K11: Chapitre 4 JESA | L11: À valider
A12: I-D1-02 | B12: Les chemins réseau critiques OT bénéficient-ils d'une redondance testée ? | C12: 3 | D12: Visibilité | E12: La redondance couvre tous les chemins critiques (contrôleurs ↔ salle de contrôle). Elle est documentée et des tests de bascule ont été réalisés. | F12: Redondance sur 100 % chemins critiques, tests de bascule documentés | G12: Architecture réseau complète, compte-rendu test de bascule | H12: Chemins critiques sans redondance ou test jamais réalisé | I12: Exiger le dernier compte-rendu de test | J12: Automatiser la bascule et mesurer le temps de récupération | K12: Chapitre 4 JESA | L12: À valider
A13: I-D1-02 | B13: Les chemins réseau critiques OT bénéficient-ils d'une redondance testée ? | C13: 4 | D13: Maîtrise & Optimisation | E13: La bascule est automatique sur défaillance. Le temps de récupération (RTO) est mesuré et inférieur à un seuil documenté. Des tests réguliers sont planifiés. | F13: Bascule automatique, RTO mesuré < seuil défini, tests planifiés annuellement | G13: Logs de bascule automatique, rapports de tests, SLA réseau | H13: RTO non mesuré ou bascule manuelle | I13: Tester en direct la bascule automatique | J13: Déployer une supervision prédictive des liaisons réseau | K13: Chapitre 4 JESA | L13: À valider
A14: I-D1-02 | B14: Les chemins réseau critiques OT bénéficient-ils d'une redondance testée ? | C14: 5 | D14: Excellence digitale supervisée | E14: Architecture réseau résiliente par conception (multi-chemins, SLA ≥ 99,99 %). Zéro interruption liée à une défaillance réseau sur 12 mois. Auto-guérison documentée. | F14: Zéro interruption réseau non planifiée sur 12 mois, SLA ≥ 99,99 % | G14: Journal des incidents réseau vierge sur 12 mois, architecture multi-chemins | H14: Toute interruption réseau dans l'année | I14: Examiner le journal d'incidents réseau sur 12 mois | J14: Niveau d'excellence | K14: Chapitre 4 JESA | L14: À valider
... A362: I-D10-06 | B362: Une veille techno et des partenariats d'innovation formalisés sont-ils actifs ? | C362: 5 | D362: Excellence digitale supervisée | E362: écosystème d'innovation reconnu externalement est pleinement optimisé, automatisé et s'améliore en continu. Les résultats dépassent les objectifs sur 12 mois. | F362: écosystème d'innovation reconnu externalement excellence, amélioration continue documentée | G362: Rapport annuel de performance, historique d'amélioration | H362: Régression ou stagnation sur les indicateurs | I362: Examiner les tendances sur 12 mois | J362: Niveau d'excellence - maintenir et partager les bonnes pratiques | K362: Chapitre 4 JESA | L362: À valider

Sheet EVIDENCE_CATALOG
A1: EVIDENCE_CATALOG — Catalogue des types de preuves acceptables
A2: Evidence_ID | B2: Evidence_Category | C2: Evidence_Name | D2: Evidence_Description | E2: Applicable_Dimensions | F2: Reliability_Level | G2: Example | H2: Confidentiality_Considerations
A3: EV-001 | B3: Architecture & Schémas | C3: Schéma réseau OT/IT | D3: Représentation graphique de l'architecture réseau industrielle incluant les équipements, connexions et zones de sécurité | E3: D1, D2, D7 | F3: Élevée | G3: Architecture réseau Youssoufia Mining 5.0 (Q12203-01-DG-DAL-00001) | H3: Confidentiel - Ne pas diffuser hors mission d'évaluation
A4: EV-002 | B4: Architecture & Schémas | C4: Architecture de système de contrôle | D4: Documentation de l'architecture DCS/SCADA incluant les contrôleurs, serveurs et postes opérateurs | E4: D1, D3, D4 | F4: Élevée | G4: Control System Architecture Q12203-01-IC-DBD-00001 | H4: Confidentiel
A5: EV-003 | B5: Architecture & Schémas | C5: Matrice d'interfaces inter-systèmes | D5: Tableau listant toutes les interfaces entre systèmes avec protocoles, formats et fréquences d'échange | E5: D2, D3, D4 | F5: Élevée | G5: Document d'interfaces DCS-SCADA-MES | H5: Interne
A6: EV-004 | B6: Configurations | C6: Configuration historian | D6: Paramètres de configuration du système d'historisation : tags collectés, fréquences, durées de rétention | E6: D5 | F6: Élevée | G6: Liste des tags historian avec paramètres | H6: Confidentiel
A7: EV-005 | B7: Configurations | C7: Configuration OPC UA | D7: Paramètres de déploiement et configuration du serveur OPC UA et des connexions clients | E7: D2, D3 | F7: Élevée | G7: Configuration OPC UA Server VM | H7: Confidentiel
A8: EV-006 | B8: Configurations | C8: Règles de firewall et de segmentation | D8: Politique de règles du pare-feu entre zones OT et IT, documentant les flux autorisés et bloqués | E8: D7 | F8: Élevée | G8: Règles firewall L2/L3 et DMZ L3.5 | H8: Très confidentiel - Restreint
A9: EV-007 | B9: Configurations | C9: Configuration Active Directory OT | D9: Paramètres de l'AD dédié aux systèmes OT : politiques de mots de passe, groupes, rôles | E9: D7 | F9: Élevée | G9: OT AD Configuration Q12203-00-DG-SPC-00013 | H9: Confidentiel
A10: EV-008 | B10: Procédures | C10: Procédure de gestion du changement | D10: Document décrivant le processus de validation et de déploiement des modifications sur les systèmes digitaux | E10: D8 | F10: Élevée | G10: Procédure MOC (Management of Change) digitale | H10: Interne
A11: EV-009 | B11: Procédures | C11: Procédure de gestion des alarmes | D11: Document décrivant la philosophie, la priorisation et la gestion des alarmes DCS/SCADA | E11: D3, D4 | F11: Élevée | G11: Alarm Management Spec Q12203-00-DG-SPC-00008 | H11: Interne
A12: EV-010 | B12: Procédures | C12: Plan de reprise d'activité OT | D12: Document décrivant les procédures de récupération après incident pour les systèmes OT critiques | E12: D1 | F12: Élevée | G12: DRP OT - Procédure de reprise des systèmes de contrôle | H12: Confidentiel
A13: EV-011 | B13: Politiques | C13: Politique de cybersécurité OT | D13: Document de politique décrivant les règles et exigences de sécurité pour les systèmes OT du site | E13: D7, D8 | F13: Élevée | G13: OT Cybersecurity Spec Q12203-00-DG-SPC-00006 | H13: Confidentiel
... A32: EV-030 | B32: Observations terrain | C32: Fiche d'observation terrain | D32: Formulaire documentant une observation directe sur le terrain : équipements, affichages, pratiques | E32: Toutes | F32: Moyenne | G32: Fiche observation salle de contrôle - Utilisation HMI | H32: Interne

Sheet QUESTIONNAIRE_TEMPLATE
A1: QUESTIONNAIRE_TEMPLATE — Feuille de saisie terrain (60 lignes)
A2: Assessment_ID | B2: Site_ID | C2: Indicator_ID | D2: Pillar_ID | E2: Dimension_ID | F2: Subdimension_ID | G2: Assessment_Question | H2: Selected_Score | I2: Evidence_Reference | J2: Evaluator_Comment | K2: Confidence_Level | L2: Applicability | M2: Validation_Status
A3: =ASSESSMENT_METADATA!B3 -> JESA-ASSESS-001 | B3: =ASSESSMENT_METADATA!B4 -> 0 | C3: I-D1-01 | D3: P1 | E3: D1 | F3: SD1.1 | G3: Quel est le % des équipements de terrain connectés au réseau OT ? | K3: Moyen | L3: Applicable | M3: Brouillon
A4: =ASSESSMENT_METADATA!B3 -> JESA-ASSESS-001 | B4: =ASSESSMENT_METADATA!B4 -> 0 | C4: I-D1-02 | D4: P1 | E4: D1 | F4: SD1.1 | G4: Les chemins réseau critiques OT bénéficient-ils d'une redondance testée ? | K4: Moyen | L4: Applicable | M4: Brouillon
A5: =ASSESSMENT_METADATA!B3 -> JESA-ASSESS-001 | B5: =ASSESSMENT_METADATA!B4 -> 0 | C5: I-D1-03 | D5: P1 | E5: D1 | F5: SD1.1 | G5: La disponibilité réseau OT est-elle mesurée et comparée à un objectif ? | K5: Moyen | L5: Applicable | M5: Brouillon
A6: =ASSESSMENT_METADATA!B3 -> JESA-ASSESS-001 | B6: =ASSESSMENT_METADATA!B4 -> 0 | C6: I-D1-04 | D6: P1 | E6: D1 | F6: SD1.2 | G6: Les serveurs OT sont-ils déployés sur une infrastructure virtualisée ? | K6: Moyen | L6: Applicable | M6: Brouillon
A7: =ASSESSMENT_METADATA!B3 -> JESA-ASSESS-001 | B7: =ASSESSMENT_METADATA!B4 -> 0 | C7: I-D1-05 | D7: P1 | E7: D1 | F7: SD1.2 | G7: Les serveurs OT disposent-ils d'une capacité de réserve ≥ 30 % ? | K7: Moyen | L7: Applicable | M7: Brouillon
A8: =ASSESSMENT_METADATA!B3 -> JESA-ASSESS-001 | B8: =ASSESSMENT_METADATA!B4 -> 0 | C8: I-D1-06 | D8: P1 | E8: D1 | F8: SD1.2 | G8: Un plan de reprise d'activité OT est-il documenté, approuvé et testé ? | K8: Moyen | L8: Applicable | M8: Brouillon
A9: =ASSESSMENT_METADATA!B3 -> JESA-ASSESS-001 | B9: =ASSESSMENT_METADATA!B4 -> 0 | C9: I-D2-01 | D9: P1 | E9: D2 | F9: SD2.1 | G9: Les échanges inter-équipements utilisent-ils des protocoles normalisés ? | K9: Moyen | L9: Applicable | M9: Brouillon
A10: =ASSESSMENT_METADATA!B3 -> JESA-ASSESS-001 | B10: =ASSESSMENT_METADATA!B4 -> 0 | C10: I-D2-02 | D10: P1 | E10: D2 | F10: SD2.1 | G10: Un serveur OPC UA est-il déployé et opérationnel ? | K10: Moyen | L10: Applicable | M10: Brouillon
A11: =ASSESSMENT_METADATA!B3 -> JESA-ASSESS-001 | B11: =ASSESSMENT_METADATA!B4 -> 0 | C11: I-D2-03 | D11: P1 | E11: D2 | F11: SD2.1 | G11: Toutes les interfaces inter-systèmes sont-elles documentées ? | K11: Moyen | L11: Applicable | M11: Brouillon
A12: =ASSESSMENT_METADATA!B3 -> JESA-ASSESS-001 | B12: =ASSESSMENT_METADATA!B4 -> 0 | C12: I-D2-04 | D12: P1 | E12: D2 | F12: SD2.2 | G12: Les données OT remontent-elles automatiquement vers les systèmes IT ? | K12: Moyen | L12: Applicable | M12: Brouillon
A13: =ASSESSMENT_METADATA!B3 -> JESA-ASSESS-001 | B13: =ASSESSMENT_METADATA!B4 -> 0 | C13: I-D2-05 | D13: P1 | E13: D2 | F13: SD2.2 | G13: Les flux OT/IT sont-ils supervisés avec alertes automatiques ? | K13: Moyen | L13: Applicable | M13: Brouillon
A14: =ASSESSMENT_METADATA!B3 -> JESA-ASSESS-001 | B14: =ASSESSMENT_METADATA!B4 -> 0 | C14: I-D2-06 | D14: P1 | E14: D2 | F14: SD2.2 | G14: La latence et le taux de disponibilité des échanges OT/IT sont-ils mesurés vs SLA ? | K14: Moyen | L14: Applicable | M14: Brouillon
A15: =ASSESSMENT_METADATA!B3 -> JESA-ASSESS-001 | B15: =ASSESSMENT_METADATA!B4 -> 0 | C15: I-D3-01 | D15: P2 | E15: D3 | F15: SD3.1 | G15: Quel % des boucles critiques est piloté par un DCS ou PLC ? | K15: Moyen | L15: Applicable | M15: Brouillon
A16: =ASSESSMENT_METADATA!B3 -> JESA-ASSESS-001 | B16: =ASSESSMENT_METADATA!B4 -> 0 | C16: I-D3-02 | D16: P2 | E16: D3 | F16: SD3.1 | G16: La configuration complète du DCS est-elle documentée et à jour ? | K16: Moyen | L16: Applicable | M16: Brouillon
A17: =ASSESSMENT_METADATA!B3 -> JESA-ASSESS-001 | B17: =ASSESSMENT_METADATA!B4 -> 0 | C17: I-D3-03 | D17: P2 | E17: D3 | F17: SD3.1 | G17: Le système d'alarmes DCS fait-il l'objet d'une gestion active et rationalisée ? | K17: Moyen | L17: Applicable | M17: Brouillon
A18: =ASSESSMENT_METADATA!B3 -> JESA-ASSESS-001 | B18: =ASSESSMENT_METADATA!B4 -> 0 | C18: I-D3-04 | D18: P2 | E18: D3 | F18: SD3.2 | G18: Un MES est-il déployé, interfacé au DCS et utilisé pour la traçabilité ? | K18: Moyen | L18: Applicable | M18: Brouillon
A19: =ASSESSMENT_METADATA!B3 -> JESA-ASSESS-001 | B19: =ASSESSMENT_METADATA!B4 -> 0 | C19: I-D3-05 | D19: P2 | E19: D3 | F19: SD3.2 | G19: L'ordonnancement de production est-il réalisé par un outil automatisé ? | K19: Moyen | L19: Applicable | M19: Brouillon
A20: =ASSESSMENT_METADATA!B3 -> JESA-ASSESS-001 | B20: =ASSESSMENT_METADATA!B4 -> 0 | C20: I-D3-06 | D20: P2 | E20: D3 | F20: SD3.2 | G20: Les écarts planifié/réel sont-ils mesurés automatiquement et documentés ? | K20: Moyen | L20: Applicable | M20: Brouillon
A21: =ASSESSMENT_METADATA!B3 -> JESA-ASSESS-001 | B21: =ASSESSMENT_METADATA!B4 -> 0 | C21: I-D4-01 | D21: P2 | E21: D4 | F21: SD4.1 | G21: Quel % des équipements est supervisé via SCADA centralisé ? | K21: Moyen | L21: Applicable | M21: Brouillon
A22: =ASSESSMENT_METADATA!B3 -> JESA-ASSESS-001 | B22: =ASSESSMENT_METADATA!B4 -> 0 | C22: I-D4-02 | D22: P2 | E22: D4 | F22: SD4.1 | G22: Les IHM sont-elles standardisées selon une charte documentée ? | K22: Moyen | L22: Applicable | M22: Brouillon
A23: =ASSESSMENT_METADATA!B3 -> JESA-ASSESS-001 | B23: =ASSESSMENT_METADATA!B4 -> 0 | C23: I-D4-03 | D23: P2 | E23: D4 | F23: SD4.1 | G23: Le taux d'alarmes nuisances SCADA est-il mesuré et géré ? | K23: Moyen | L23: Applicable | M23: Brouillon
A24: =ASSESSMENT_METADATA!B3 -> JESA-ASSESS-001 | B24: =ASSESSMENT_METADATA!B4 -> 0 | C24: I-D4-04 | D24: P2 | E24: D4 | F24: SD4.2 | G24: Quel % des équipements critiques a des capteurs de condition ? | K24: Moyen | L24: Applicable | M24: Brouillon
A25: =ASSESSMENT_METADATA!B3 -> JESA-ASSESS-001 | B25: =ASSESSMENT_METADATA!B4 -> 0 | C25: I-D4-05 | D25: P2 | E25: D4 | F25: SD4.2 | G25: Un système CBMS est-il opérationnel et utilisé par la maintenance ? | K25: Moyen | L25: Applicable | M25: Brouillon
A26: =ASSESSMENT_METADATA!B3 -> JESA-ASSESS-001 | B26: =ASSESSMENT_METADATA!B4 -> 0 | C26: I-D4-06 | D26: P2 | E26: D4 | F26: SD4.2 | G26: Des modèles prédictifs de défaillance sont-ils actifs en production ? | K26: Moyen | L26: Applicable | M26: Brouillon
A27: =ASSESSMENT_METADATA!B3 -> JESA-ASSESS-001 | B27: =ASSESSMENT_METADATA!B4 -> 0 | C27: I-D5-01 | D27: P3 | E27: D5 | F27: SD5.1 | G27: Un historian couvre-t-il ≥ 80 % des points de mesure critiques ? | K27: Moyen | L27: Applicable | M27: Brouillon
A28: =ASSESSMENT_METADATA!B3 -> JESA-ASSESS-001 | B28: =ASSESSMENT_METADATA!B4 -> 0 | C28: I-D5-02 | D28: P3 | E28: D5 | F28: SD5.1 | G28: La rétention historian est-elle ≥ 12 mois sur les variables critiques ? | K28: Moyen | L28: Applicable | M28: Brouillon
A29: =ASSESSMENT_METADATA!B3 -> JESA-ASSESS-001 | B29: =ASSESSMENT_METADATA!B4 -> 0 | C29: I-D5-03 | D29: P3 | E29: D5 | F29: SD5.1 | G29: Chaque donnée est-elle traçable jusqu'à sa source primaire ? | K29: Moyen | L29: Applicable | M29: Brouillon
A30: =ASSESSMENT_METADATA!B3 -> JESA-ASSESS-001 | B30: =ASSESSMENT_METADATA!B4 -> 0 | C30: I-D5-04 | D30: P3 | E30: D5 | F30: SD5.2 | G30: Une politique de qualité des données est-elle formalisée et approuvée ? | K30: Moyen | L30: Applicable | M30: Brouillon
A31: =ASSESSMENT_METADATA!B3 -> JESA-ASSESS-001 | B31: =ASSESSMENT_METADATA!B4 -> 0 | C31: I-D5-05 | D31: P3 | E31: D5 | F31: SD5.2 | G31: Un référentiel de données industrielles est-il documenté et maintenu ? | K31: Moyen | L31: Applicable | M31: Brouillon
A32: =ASSESSMENT_METADATA!B3 -> JESA-ASSESS-001 | B32: =ASSESSMENT_METADATA!B4 -> 0 | C32: I-D5-06 | D32: P3 | E32: D5 | F32: SD5.2 | G32: La qualité des données est-elle mesurée automatiquement vs objectif ? | K32: Moyen | L32: Applicable | M32: Brouillon
A33: =ASSESSMENT_METADATA!B3 -> JESA-ASSESS-001 | B33: =ASSESSMENT_METADATA!B4 -> 0 | C33: I-D6-01 | D33: P3 | E33: D6 | F33: SD6.1 | G33: Des tableaux de bord KPI sont-ils disponibles en temps réel sans saisie manuelle ? | K33: Moyen | L33: Applicable | M33: Brouillon
A34: =ASSESSMENT_METADATA!B3 -> JESA-ASSESS-001 | B34: =ASSESSMENT_METADATA!B4 -> 0 | C34: I-D6-02 | D34: P3 | E34: D6 | F34: SD6.1 | G34: Une plateforme BI industrielle est-elle déployée et utilisée régulièrement ? | K34: Moyen | L34: Applicable | M34: Brouillon
A35: =ASSESSMENT_METADATA!B3 -> JESA-ASSESS-001 | B35: =ASSESSMENT_METADATA!B4 -> 0 | C35: I-D6-03 | D35: P3 | E35: D6 | F35: SD6.1 | G35: Les analyses de causes racines sont-elles réalisées avec méthode structurée ? | K35: Moyen | L35: Applicable | M35: Brouillon
A36: =ASSESSMENT_METADATA!B3 -> JESA-ASSESS-001 | B36: =ASSESSMENT_METADATA!B4 -> 0 | C36: I-D6-04 | D36: P3 | E36: D6 | F36: SD6.2 | G36: Au moins 1 modèle ML est-il en production sur données industrielles réelles ? | K36: Moyen | L36: Applicable | M36: Brouillon
A37: =ASSESSMENT_METADATA!B3 -> JESA-ASSESS-001 | B37: =ASSESSMENT_METADATA!B4 -> 0 | C37: I-D6-05 | D37: P3 | E37: D6 | F37: SD6.2 | G37: Le pipeline de données ML est-il documenté, automatisé et opérationnel ? | K37: Moyen | L37: Applicable | M37: Brouillon
A38: =ASSESSMENT_METADATA!B3 -> JESA-ASSESS-001 | B38: =ASSESSMENT_METADATA!B4 -> 0 | C38: I-D6-06 | D38: P3 | E38: D6 | F38: SD6.2 | G38: Les modèles IA ont-ils produit un gain documenté et quantifié sur un KPI ? | K38: Moyen | L38: Applicable | M38: Brouillon
A39: =ASSESSMENT_METADATA!B3 -> JESA-ASSESS-001 | B39: =ASSESSMENT_METADATA!B4 -> 0 | C39: I-D7-01 | D39: P4 | E39: D7 | F39: SD7.1 | G39: Un firewall dédié sépare-t-il les réseaux OT et IT ? | K39: Moyen | L39: Applicable | M39: Brouillon
A40: =ASSESSMENT_METADATA!B3 -> JESA-ASSESS-001 | B40: =ASSESSMENT_METADATA!B4 -> 0 | C40: I-D7-02 | D40: P4 | E40: D7 | F40: SD7.1 | G40: Une DMZ OT (L3.5) dédiée est-elle déployée et opérationnelle ? | K40: Moyen | L40: Applicable | M40: Brouillon
...

Sheet CALCULATION_RULES
A1: CALCULATION_RULES — Règles de calcul du moteur d'évaluation (Assessment Engine)
A3: 1. RÈGLES DE NOTATION DES INDICATEURS
A4: R1 — Note entière | B4: Chaque indicateur reçoit une note entière comprise entre 0 et 5 inclus. Les notes décimales sont exclues : elles introduiraient une fausse précision incompatible avec la reproductibilité inter-évaluateurs. Source : Chapitre 4 JESA, section 4.4.2.
A5: 2. GESTION DES CAS PARTICULIERS
A6: Indicateurs non applicables | B6: Si un indicateur est marqué 'Non applicable' dans QUESTIONNAIRE_TEMPLATE (colonne Applicability), il est exclu du calcul de la moyenne plafonnée. La formule s'applique sur les N indicateurs applicables restants (N pouvant être 1 ou 2). Si tous les indicateurs d'une SD sont non applicables, le score SD = NA et la SD est exclue du calcul de la dimension avec rééquilibrage des poids.
A7: Poids invalides | B7: Si la somme des poids effectifs d'un niveau ne vaut pas 1,0 (±0,001), l'Assessment Engine doit refuser le calcul et afficher un message d'erreur identifiant le niveau et le parent concernés. Contrôle documenté dans QUALITY_CONTROL.
A8: Contrôle des cibles | B8: La cible doit être un entier entre 0 et 5. Si Target_Level_User est inférieur au score actuel calculé, l'Assessment Engine affiche un avertissement mais ne bloque pas le calcul. L'évaluateur doit documenter la justification dans TARGET_LEVELS.
